Traceback (most recent call last):
  File "/Users/Tetsu/anaconda3/envs/JupyterBook/lib/python3.8/site-packages/jupyter_cache/executors/basic.py", line 157, in execute
    executenb(nb_bundle.nb, cwd=tmpdirname)
  File "/Users/Tetsu/anaconda3/envs/JupyterBook/lib/python3.8/site-packages/nbconvert/preprocessors/execute.py", line 737, in executenb
    return ep.preprocess(nb, resources, km=km)[0]
  File "/Users/Tetsu/anaconda3/envs/JupyterBook/lib/python3.8/site-packages/nbconvert/preprocessors/execute.py", line 405, in preprocess
    nb, resources = super(ExecutePreprocessor, self).preprocess(nb, resources)
  File "/Users/Tetsu/anaconda3/envs/JupyterBook/lib/python3.8/site-packages/nbconvert/preprocessors/base.py", line 69, in preprocess
    nb.cells[index], resources = self.preprocess_cell(cell, resources, index)
  File "/Users/Tetsu/anaconda3/envs/JupyterBook/lib/python3.8/site-packages/nbconvert/preprocessors/execute.py", line 448, in preprocess_cell
    raise CellExecutionError.from_cell_and_msg(cell, out)
nbconvert.preprocessors.execute.CellExecutionError: An error occurred while executing the following cell:
------------------
(s0+s1*d0)/(1-s1*d1), s1*d2/(1-s1*d1), (d0+d1*s0)/(1-s1*d1), d2
------------------

[0;31m---------------------------------------------------------------------------[0m
[0;31mNameError[0m                                 Traceback (most recent call last)
[0;32m<ipython-input-26-10a8f5dda26e>[0m in [0;36m<module>[0;34m[0m
[0;32m----> 1[0;31m [0;34m([0m[0ms0[0m[0;34m+[0m[0ms1[0m[0;34m*[0m[0md0[0m[0;34m)[0m[0;34m/[0m[0;34m([0m[0;36m1[0m[0;34m-[0m[0ms1[0m[0;34m*[0m[0md1[0m[0;34m)[0m[0;34m,[0m [0ms1[0m[0;34m*[0m[0md2[0m[0;34m/[0m[0;34m([0m[0;36m1[0m[0;34m-[0m[0ms1[0m[0;34m*[0m[0md1[0m[0;34m)[0m[0;34m,[0m [0;34m([0m[0md0[0m[0;34m+[0m[0md1[0m[0;34m*[0m[0ms0[0m[0;34m)[0m[0;34m/[0m[0;34m([0m[0;36m1[0m[0;34m-[0m[0ms1[0m[0;34m*[0m[0md1[0m[0;34m)[0m[0;34m,[0m [0md2[0m[0;34m[0m[0;34m[0m[0m
[0m
[0;31mNameError[0m: name 's0' is not defined
NameError: name 's0' is not defined

