Traceback (most recent call last):
  File "/Users/Tetsu/anaconda3/envs/JupyterBook/lib/python3.8/site-packages/jupyter_cache/executors/basic.py", line 157, in execute
    executenb(nb_bundle.nb, cwd=tmpdirname)
  File "/Users/Tetsu/anaconda3/envs/JupyterBook/lib/python3.8/site-packages/nbconvert/preprocessors/execute.py", line 737, in executenb
    return ep.preprocess(nb, resources, km=km)[0]
  File "/Users/Tetsu/anaconda3/envs/JupyterBook/lib/python3.8/site-packages/nbconvert/preprocessors/execute.py", line 405, in preprocess
    nb, resources = super(ExecutePreprocessor, self).preprocess(nb, resources)
  File "/Users/Tetsu/anaconda3/envs/JupyterBook/lib/python3.8/site-packages/nbconvert/preprocessors/base.py", line 69, in preprocess
    nb.cells[index], resources = self.preprocess_cell(cell, resources, index)
  File "/Users/Tetsu/anaconda3/envs/JupyterBook/lib/python3.8/site-packages/nbconvert/preprocessors/execute.py", line 448, in preprocess_cell
    raise CellExecutionError.from_cell_and_msg(cell, out)
nbconvert.preprocessors.execute.CellExecutionError: An error occurred while executing the following cell:
------------------
from scipy.stats import logistic, norm, chi2
import numpy as np
import matplotlib.pyplot as plt
from see import *
import pandas as pd
from statsmodels.formula.api import logit, probit
from statsmodels.formula.api import ols
from wooldridge import *
from py4etrics.hetero_test import *
------------------

[0;31m---------------------------------------------------------------------------[0m
[0;31mModuleNotFoundError[0m                       Traceback (most recent call last)
[0;32m<ipython-input-1-357fe0115f5c>[0m in [0;36m<module>[0;34m[0m
[1;32m      7[0m [0;32mfrom[0m [0mstatsmodels[0m[0;34m.[0m[0mformula[0m[0;34m.[0m[0mapi[0m [0;32mimport[0m [0mols[0m[0;34m[0m[0;34m[0m[0m
[1;32m      8[0m [0;32mfrom[0m [0mwooldridge[0m [0;32mimport[0m [0;34m*[0m[0;34m[0m[0;34m[0m[0m
[0;32m----> 9[0;31m [0;32mfrom[0m [0mpy4etrics[0m[0;34m.[0m[0mhetero_test[0m [0;32mimport[0m [0;34m*[0m[0;34m[0m[0;34m[0m[0m
[0m
[0;31mModuleNotFoundError[0m: No module named 'py4etrics'
ModuleNotFoundError: No module named 'py4etrics'

